<robot name="my_tag_car">
    <!-- base footprint part -->
    <link name="base_footprint">
        <!-- <inertial>
            <origin xyz="0.0 0.0 0.0" rpy="0.0 0.0 0.0"/>
            <mass value="0.01"/>
            <inertia ixx="1.6e-9" ixy="0.0" ixz="0.0" iyy="1.6e-9" iyz="0.0" izz="1.6e-9"/>
        </inertial>    -->
        <visual>
            <geometry>
                <box size="0.001 0.001 0.001" /> 
            </geometry>
        </visual>
        <collision>
            <geometry>
                <box size="0.001 0.001 0.001" /> 
            </geometry>
            <friction>
                <ode>
                    <mu>0.00</mu>
                    <mu2>0.00</mu2>
                </ode>
            </friction>
        </collision>
    </link>
    <gazebo reference="base_footprint" >
        <material>Gazebo/Red</material>
        <turnGravityOff>true</turnGravityOff>
    </gazebo>

    <!-- apriltag part -->
    <link name="april_tag">
        <inertial>
            <origin xyz="0.0 0.0 0.0" rpy="0.0 0.0 0.0"/>
            <mass value="1.0"/>
            <inertia ixx="0.042" ixy="0.0" ixz="0.0" iyy="0.042" iyz="0.0" izz="0.042"/>
        </inertial>
        <visual>
            <geometry>
                <mesh filename="package://rotors_description/urdf/apriltag2-2.dae" />
            </geometry>
            <origin xyz="0 0 0" rpy="0 0 0" />
        </visual>
        <collision>
            <geometry>
                <mesh filename="package://rotors_description/urdf/apriltag2-2.dae" />
            </geometry> 
            <friction>
                <ode>
                    <mu>0.00</mu>
                    <mu2>0.00</mu2>
                </ode>
            </friction>
        </collision>
    </link>
    <gazebo reference="april_tag" >
        <!-- <material>Gazebo/Red</material> -->
        <turnGravityOff>true</turnGravityOff>
    </gazebo>

    <!-- driver part -->
    <link name="right_driver">
    <visual>
      <origin rpy="1.570796327 0  0 " xyz="0 0 0"/>
      <geometry>
        <cylinder length="0.02" radius="0.04"/>
      </geometry>
      <material name="driver_color" >
        <color rgba="1 1 1 0.5" />
      </material>
    </visual>
    <collision>
      <origin rpy="1.570796327 0 0 " xyz="0 0 0"/>
      <geometry>
        <cylinder length="0.02" radius="0.04"/>
      </geometry>
    </collision>
    <inertial>
      <mass value="2.5"/>
      <origin xyz="0 0 0"/>
      <inertia ixx="0.00108333333333" ixy="0" ixz="0" iyy="0.00108333333333" iyz="0" izz="0.002"/>
    </inertial>
    </link>
    <gazebo reference="right_driver" >
        <material>Gazebo/Red</material>
        <turnGravityOff>false</turnGravityOff>
    </gazebo>

    <link name="left_driver">
    <visual>
      <origin rpy="1.570796327 0 0" xyz="0 0 0"/>
      <geometry>
        <cylinder length="0.02" radius="0.04"/>
      </geometry>
      <material name="driver_color" >
        <color rgba="1 1 1 0.5" />
      </material>
    </visual>
    <collision>
      <origin rpy="1.570796327 0 0 " xyz="0 0 0"/>
      <geometry>
        <cylinder length="0.02" radius="0.04"/>
      </geometry>
    </collision>
    <inertial>
      <mass value="2.5"/>
      <origin xyz="0 0 0"/>
      <inertia ixx="0.00108333333333" ixy="0" ixz="0" iyy="0.00108333333333" iyz="0" izz="0.002"/>
    </inertial>
    </link>
    <gazebo reference="left_driver" >
        <material>Gazebo/Red</material>
        <turnGravityOff>false</turnGravityOff>
    </gazebo>

    <link name="caster_front_link">
    <visual>
      <origin rpy="0 0 0" xyz="0 0 0"/>
      <geometry>
        <sphere radius="0.05"/>
      </geometry>
      <material name="Black"/>
    </visual>
    <collision>
        <geometry>
            <sphere radius="0.05"/>
        </geometry>
        <origin rpy="0 0 0" xyz="0 0 0"/>
    </collision>
    <inertial>
        <mass value="0.2"/>
        <origin xyz="0 0 0"/>
        <inertia ixx="0.001" ixy="0.0" ixz="0.0" iyy="0.001" iyz="0.0" izz="0.001"/>
    </inertial>
    </link>
    <gazebo reference="caster_front_link">
        <turnGravityOff>false</turnGravityOff>
    </gazebo>

    <link name="caster_back_link"> 
    <visual>
        <origin rpy="0 0 0" xyz="0 0 0"/>
        <geometry>
            <sphere radius="0.05"/>
        </geometry>
        <material name="Black"/>
    </visual>
    <collision>
        <geometry>
            <sphere radius="0.05"/>
        </geometry>
        <origin rpy="0 0 0" xyz="0 0 0"/>
    </collision>
    <inertial>
        <mass value="0.2"/>
        <origin xyz="0 0 0"/>
        <inertia ixx="0.001" ixy="0.0" ixz="0.0" iyy="0.001" iyz="0.0" izz="0.001"/>
    </inertial>
    </link>
    <gazebo reference="caster_back_link">
        <turnGravityOff>false</turnGravityOff>
    </gazebo>


    <!-- joint part -->
    <joint name="tag2footprint" type="fixed">
        <parent link="base_footprint" />
        <child link="april_tag" />
        <origin xyz="0 0 0.25" rpy="0.0 0.0 0.0" />
    </joint>
    <!-- driver joint part -->
    <joint name="base_l_wheel_joint" type="continuous">
        <parent link="april_tag" />
        <child link="left_driver" />
        <origin xyz="0 0.2 -0.215" rpy="0.0 0.0 0.0" />
        <axis xyz="0 1 0" />
    </joint>
    <joint name="base_r_wheel_joint" type="continuous">
        <parent link="april_tag" />
        <child link="right_driver" />
        <origin xyz="0 -0.2 -0.215" rpy="0.0 0.0 0.0" />
        <axis xyz="0 1 0" />
    </joint>
    <joint name="caster_front_joint" type="fixed">
        <parent link="april_tag"/>
        <child link="caster_front_link"/>
        <origin rpy="-1.57079632679 0 0" xyz="0.2 0.0 -0.205"/>
    </joint>
    <joint name="caster_back_joint" type="fixed">
        <parent link="april_tag"/>
        <child link="caster_back_link"/>
        <origin rpy="-1.57079632679 0 0" xyz="-0.2 0.0 -0.205"/>
    </joint>
    
    <gazebo>
        <plugin filename="libgazebo_ros_diff_drive.so" name="differential_drive_controller_front">
            <rosDebugLevel>Debug</rosDebugLevel>
            <publishWheelTF>True</publishWheelTF>
            <publishTf>1</publishTf>
            <publishWheelJointState>true</publishWheelJointState>
            <alwaysOn>true</alwaysOn>
            <updateRate>100.0</updateRate>
            <leftJoint>base_l_wheel_joint</leftJoint>
            <rightJoint>base_r_wheel_joint</rightJoint>
            <wheelSeparation>0.4</wheelSeparation>
            <wheelDiameter>0.2</wheelDiameter>
            <broadcastTF>1</broadcastTF>
            <wheelTorque>30</wheelTorque>
            <wheelAcceleration>1.8</wheelAcceleration>
            <commandTopic>cmd_vel</commandTopic>
            <odometryFrame>odom</odometryFrame>
            <odometryTopic>odom</odometryTopic>
            <robotBaseFrame>base_footprint</robotBaseFrame>
        </plugin>
    </gazebo>

</robot>